Workbook

Sheet 1025
A1: Column1.name | B1: Column1.url | C1: Column1.url
A2: bulbasaur | B2: https://pokeapi.co/api/v2/pokemon/1/ | C2: 1
A3: ivysaur | B3: https://pokeapi.co/api/v2/pokemon/2/ | C3: 2
A4: venusaur | B4: https://pokeapi.co/api/v2/pokemon/3/ | C4: 3
A5: charmander | B5: https://pokeapi.co/api/v2/pokemon/4/ | C5: 4
A6: charmeleon | B6: https://pokeapi.co/api/v2/pokemon/5/ | C6: 5
A7: charizard | B7: https://pokeapi.co/api/v2/pokemon/6/ | C7: 6
A8: squirtle | B8: https://pokeapi.co/api/v2/pokemon/7/ | C8: 7
A9: wartortle | B9: https://pokeapi.co/api/v2/pokemon/8/ | C9: 8
A10: blastoise | B10: https://pokeapi.co/api/v2/pokemon/9/ | C10: 9
A11: caterpie | B11: https://pokeapi.co/api/v2/pokemon/10/ | C11: 10
A12: metapod | B12: https://pokeapi.co/api/v2/pokemon/11/ | C12: 11
A13: butterfree | B13: https://pokeapi.co/api/v2/pokemon/12/ | C13: 12
... A1329: falinks-mega | B1329: https://pokeapi.co/api/v2/pokemon/10303/ | C1329: 10303

Sheet Planilha1
A2: Chikorita | B2: =VLOOKUP(A2,'1025'!A:C,3,0) -> 152 | D2: chikorita | E2: ="'"&D2&"': "&B2&"," -> 'chikorita': 152,
A3: Bayleef | B3: =VLOOKUP(A3,'1025'!A:C,3,0) -> 153 | D3: bayleef | E3: ="'"&D3&"': "&B3&"," -> 'bayleef': 153,
A4: Meganium | B4: =VLOOKUP(A4,'1025'!A:C,3,0) -> 154 | D4: meganium | E4: ="'"&D4&"': "&B4&"," -> 'meganium': 154,
A5: Tepig | B5: =VLOOKUP(A5,'1025'!A:C,3,0) -> 498 | D5: tepig | E5: ="'"&D5&"': "&B5&"," -> 'tepig': 498,
A6: Pignite | B6: =VLOOKUP(A6,'1025'!A:C,3,0) -> 499 | D6: pignite | E6: ="'"&D6&"': "&B6&"," -> 'pignite': 499,
A7: Emboar | B7: =VLOOKUP(A7,'1025'!A:C,3,0) -> 500 | D7: emboar | E7: ="'"&D7&"': "&B7&"," -> 'emboar': 500,
A8: Totodile | B8: =VLOOKUP(A8,'1025'!A:C,3,0) -> 158 | D8: totodile | E8: ="'"&D8&"': "&B8&"," -> 'totodile': 158,
A9: Croconaw | B9: =VLOOKUP(A9,'1025'!A:C,3,0) -> 159 | D9: croconaw | E9: ="'"&D9&"': "&B9&"," -> 'croconaw': 159,
A10: Feraligatr | B10: =VLOOKUP(A10,'1025'!A:C,3,0) -> 160 | D10: feraligatr | E10: ="'"&D10&"': "&B10&"," -> 'feraligatr': 160,
A11: Fletchling | B11: =VLOOKUP(A11,'1025'!A:C,3,0) -> 661 | D11: fletchling | E11: ="'"&D11&"': "&B11&"," -> 'fletchling': 661,
A12: Fletchinder | B12: =VLOOKUP(A12,'1025'!A:C,3,0) -> 662 | D12: fletchinder | E12: ="'"&D12&"': "&B12&"," -> 'fletchinder': 662,
A13: Talonflame | B13: =VLOOKUP(A13,'1025'!A:C,3,0) -> 663 | D13: talonflame | E13: ="'"&D13&"': "&B13&"," -> 'talonflame': 663,
... A38: Starmie | B38: =VLOOKUP(A38,'1025'!A:C,3,0) -> 121 | D38: starmie | E38: ="'"&D38&"': "&B38&"," -> 'starmie': 121,
A39: Flabébé | B39: 669 | D39: flabébé | E39: ="'"&D39&"': "&B39&"," -> 'flabébé': 669,
A40: Floette | B40: =VLOOKUP(A40,'1025'!A:C,3,0) -> 670 | D40: floette | E40: ="'"&D40&"': "&B40&"," -> 'floette': 670,
A41: Florges | B41: =VLOOKUP(A41,'1025'!A:C,3,0) -> 671 | D41: florges | E41: ="'"&D41&"': "&B41&"," -> 'florges': 671,
A42: Skiddo | B42: =VLOOKUP(A42,'1025'!A:C,3,0) -> 672 | D42: skiddo | E42: ="'"&D42&"': "&B42&"," -> 'skiddo': 672,
A43: Gogoat | B43: =VLOOKUP(A43,'1025'!A:C,3,0) -> 673 | D43: gogoat | E43: ="'"&D43&"': "&B43&"," -> 'gogoat': 673,
A44: Espurr | B44: =VLOOKUP(A44,'1025'!A:C,3,0) -> 677 | D44: espurr | E44: ="'"&D44&"': "&B44&"," -> 'espurr': 677,
A45: Meowstic | B45: 678 | D45: meowstic | E45: ="'"&D45&"': "&B45&"," -> 'meowstic': 678,
A46: Litleo | B46: =VLOOKUP(A46,'1025'!A:C,3,0) -> 667 | D46: litleo | E46: ="'"&D46&"': "&B46&"," -> 'litleo': 667,
A47: Pyroar | B47: =VLOOKUP(A47,'1025'!A:C,3,0) -> 668 | D47: pyroar | E47: ="'"&D47&"': "&B47&"," -> 'pyroar': 668,
A48: Pancham | B48: =VLOOKUP(A48,'1025'!A:C,3,0) -> 674 | D48: pancham | E48: ="'"&D48&"': "&B48&"," -> 'pancham': 674,
A49: Pangoro | B49: =VLOOKUP(A49,'1025'!A:C,3,0) -> 675 | D49: pangoro | E49: ="'"&D49&"': "&B49&"," -> 'pangoro': 675,
A50: Trubbish | B50: =VLOOKUP(A50,'1025'!A:C,3,0) -> 568 | D50: trubbish | E50: ="'"&D50&"': "&B50&"," -> 'trubbish': 568,
A51: Garbodor | B51: =VLOOKUP(A51,'1025'!A:C,3,0) -> 569 | D51: garbodor | E51: ="'"&D51&"': "&B51&"," -> 'garbodor': 569,
A52: Dedenne | B52: =VLOOKUP(A52,'1025'!A:C,3,0) -> 702 | D52: dedenne | E52: ="'"&D52&"': "&B52&"," -> 'dedenne': 702,
A53: Pichu | B53: =VLOOKUP(A53,'1025'!A:C,3,0) -> 172 | D53: pichu | E53: ="'"&D53&"': "&B53&"," -> 'pichu': 172,
A54: Pikachu | B54: =VLOOKUP(A54,'1025'!A:C,3,0) -> 25 | D54: pikachu | E54: ="'"&D54&"': "&B54&"," -> 'pikachu': 25,
A55: Raichu | B55: =VLOOKUP(A55,'1025'!A:C,3,0) -> 26 | D55: raichu | E55: ="'"&D55&"': "&B55&"," -> 'raichu': 26,
A56: Cleffa | B56: =VLOOKUP(A56,'1025'!A:C,3,0) -> 173 | D56: cleffa | E56: ="'"&D56&"': "&B56&"," -> 'cleffa': 173,
A57: Clefairy | B57: =VLOOKUP(A57,'1025'!A:C,3,0) -> 35 | D57: clefairy | E57: ="'"&D57&"': "&B57&"," -> 'clefairy': 35,
... A73: Doublade | B73: =VLOOKUP(A73,'1025'!A:C,3,0) -> 680 | D73: doublade | E73: ="'"&D73&"': "&B73&"," -> 'doublade': 680,
A74: Aegislash | B74: 681 | D74: aegislash | E74: ="'"&D74&"': "&B74&"," -> 'aegislash': 681,
A75: Bellsprout | B75: =VLOOKUP(A75,'1025'!A:C,3,0) -> 69 | D75: bellsprout | E75: ="'"&D75&"': "&B75&"," -> 'bellsprout': 69,
A76: Weepinbell | B76: =VLOOKUP(A76,'1025'!A:C,3,0) -> 70 | D76: weepinbell | E76: ="'"&D76&"': "&B76&"," -> 'weepinbell': 70,
A77: Victreebel | B77: =VLOOKUP(A77,'1025'!A:C,3,0) -> 71 | D77: victreebel | E77: ="'"&D77&"': "&B77&"," -> 'victreebel': 71,
A78: Pansage | B78: =VLOOKUP(A78,'1025'!A:C,3,0) -> 511 | D78: pansage | E78: ="'"&D78&"': "&B78&"," -> 'pansage': 511,
A79: Simisage | B79: =VLOOKUP(A79,'1025'!A:C,3,0) -> 512 | D79: simisage | E79: ="'"&D79&"': "&B79&"," -> 'simisage': 512,
A80: Pansear | B80: =VLOOKUP(A80,'1025'!A:C,3,0) -> 513 | D80: pansear | E80: ="'"&D80&"': "&B80&"," -> 'pansear': 513,
...
